<?xml version="1.0"?>
<robot name="tracer_v1">
    <!-- Base link -->
    <link name="base_link">
        <visual>
            <origin xyz="0 0 0" rpy="1.57 0 0"/>
            <!--<origin xyz="0 0 0" rpy="0 0 0"/>-->
            <geometry>
                <mesh filename="package://tracer_description/meshes/tracer_base_link_no_wheel.dae" />
                <!--<box size="${base_x_size} ${base_y_size} ${base_z_size}"/>-->
            </geometry>
        </visual>
        <collision>
            <!--origin
            xyz="-0.0145261552504705 0.0231316650320557 0.00586280190939592"
            rpy="0 0 0" /-->
            <origin xyz="0 0 0" rpy="1.57 0 0"/>
            <geometry>
            <mesh
                filename="package://tracer_description/meshes/tracer_base_link_no_wheel.dae" />
                <!--<box size="${base_x_size} ${base_y_size} ${base_z_size}"/>-->
            </geometry>
        </collision>
    </link>

    <!-- <joint name="chassis_link_joint" type="fixed">
        <origin xyz="0 0 ${wheel_radius - wheel_vertical_offset}" rpy="0 0 0" />
        <parent link="base_link" />
        <child link="chassis_link" />
    </joint> -->

    <!-- Robot Footprint -->
    <link name="base_footprint"/>

    <joint name="base_joint" type="fixed">
        <parent link="base_footprint"/>
        <child link="base_link"/>
        <origin xyz="0.0 0.0 0.14" rpy="0 0 0"/>
    </joint>


    <!-- laser link -->
    <link name="laser_link">
        <visual>
        <origin xyz="0 0 0" rpy="0 0 0"/>
        <geometry>
            <cylinder length="0.02" radius="0.02"/>
        </geometry>
        <material name="black">
            <color rgba="0.0 0.0 0.0 0.5" /> 
        </material>
        </visual>
    </link>
        
    <!-- laser joint -->
    <joint name="laser_joint" type="fixed">
        <parent link="base_link" />
        <child link="laser_link" />
        <origin xyz="0 0 0.03" />
    </joint>

    <link name="imu_link">
        <visual>
        <origin xyz="0 0 0.0" rpy="0 0 0"/>
        <geometry>
                <box size="0.02 0.02 0.02"/>
        </geometry>
        </visual>
    </link>

    <!-- imu joint -->
    <joint name="imu_joint" type="fixed">
        <parent link="base_link" />
        <child link="imu_link" />
        <origin xyz="0 0 0.01" />
    </joint>


    <link name="right_wheel_link">
        <visual>
            <origin xyz="0 0 0" rpy="0 0 0" />
            <geometry>
                <mesh filename="package://tracer_description/meshes/tracer_wheel.dae" />
                <!--<cylinder length="0.0787019" radius="0.0457774"/>-->
            </geometry>
        </visual>
        <inertial>
                <mass value="6" />
                <origin xyz="0 0 0" />
                <inertia ixx="0.7171" ixy="0" ixz="0" iyy="0.1361" iyz="0" izz="0.7171" />
                <!--<inertia ixx="0" ixy="0" ixz="0" iyy="0" iyz="0" izz="0" />-->
        </inertial>
        <collision>
            <origin
            xyz="0 0 0"
            rpy="0 0 0" />
            <geometry>
                <mesh filename="package://tracer_description/meshes/tracer_wheel.dae" />
                !--<cylinder length="0.0787019" radius="0.0457774"/>-->
            </geometry>
        </collision>
    </link>

    <joint name="right_wheel" type="continuous">
        <!--<origin
                xyz="0.14547 0.20835 -0.07424"
                rpy="0 1.57 0" />-->
        <parent link="base_link"/>
        <child link="right_wheel_link"/>
        <origin xyz="0 -0.167575 -0.082" rpy="0 0 0" />
        <axis xyz="0 1 0" rpy="0 0 0" />
    </joint>

    <link name="left_wheel_link">
        <visual>
            <origin xyz="0 0 0" rpy="0 0 0" />
            <geometry>
                <mesh filename="package://tracer_description/meshes/tracer_wheel.dae" />
                <!--<cylinder length="0.0787019" radius="0.0457774"/>-->
            </geometry>
        </visual>
        <inertial>
                <mass value="6" />
                <origin xyz="0 0 0" />
                <inertia ixx="0.7171" ixy="0" ixz="0" iyy="0.1361" iyz="0" izz="0.7171" />
                <!--<inertia ixx="0" ixy="0" ixz="0" iyy="0" iyz="0" izz="0" />-->
        </inertial>
        <collision>
            <origin
            xyz="0 0 0"
            rpy="0 0 0" />
            <geometry>
                <mesh filename="package://tracer_description/meshes/tracer_wheel.dae" />
                <!--<cylinder length="0.0787019" radius="0.0457774"/>-->
            </geometry>
        </collision>
    </link>

    <joint name="left_wheel" type="continuous">
        <!--<origin
                xyz="-0.17453 0.20835 -0.07424"
                rpy="0 -1.57 0" />-->
        <parent link="base_link"/>
        <child link="left_wheel_link"/>
        <origin xyz="0 0.167575 -0.082" rpy="3.14 0 0" />
        <axis xyz="0 1 0" rpy="0 0 0" />
    </joint>

    <link name="fl_castor_link">
        <visual>
            <origin xyz="0 0 0" rpy="0 0 0" />
            <geometry>
                <!--<cylinder length="${castor_length}" radius="${castor_radius}"/>-->
                <mesh filename="package://tracer_description/meshes/castor_joint.dae" />
            </geometry>
            <!--<material name="black">
                <color rgba="255 255 255 1"/>
            </material>-->
        </visual>
        <inertial>
            <mass value="1" />
            <origin xyz="0 0 0" />
            <inertia ixx="0.7171" ixy="0" ixz="0" iyy="0.1361" iyz="0" izz="0.7171" />
        </inertial>
    </link>

    <joint name="fl_castor_wheel" type="continuous">
        <parent link="base_link" />
        <child link="fl_castor_link" />
        <origin xyz="0.18905 0.167575 -0.0380886" rpy="-1.57 0 0" />
        <axis xyz="0 1 0" rpy="0 0 0" />
    </joint>

    <link name="fl_wheel_link">
        <visual>
            <origin xyz="0 0 0" rpy="0 0 0" />
            <geometry>
                <!--<cylinder length="0.04653" radius="0.036"/>-->
                <!--<sphere radius="0.0457774"/>-->
                <mesh filename="package://tracer_description/meshes/castor.dae" />
            </geometry>
            <!--<material name="black">
                <color rgba="255 255 255 1"/>
            </material>-->
        </visual>
        <inertial>
            <mass value="1" />
            <origin xyz="0 0 0" />
            <inertia ixx="0.3131" ixy="0" ixz="0" iyy="0.3131" iyz="0" izz="0.1361" />
            <!--<inertia ixx="0" ixy="0" ixz="0" iyy="0" iyz="0" izz="0" />-->
        </inertial>
        <collision>
            <origin
            xyz="0 0 0"
            rpy="0 0 0" />
            <geometry>
                <!--<cylinder length="0.04653" radius="0.036"/>-->
                <!--<cylinder length="0.0787019" radius="0.0457774"/>-->
                <!--<sphere radius="0.0457774"/>-->
                <mesh filename="package://tracer_description/meshes/castor.dae" />
            </geometry>
        </collision>
    </link>

    <joint name="fl_wheel" type="continuous">
        <!-- <origin
                xyz="0.14547 0.20835 -0.07424"
                rpy="0 1.57 0" /> -->
        <parent link="fl_castor_link"/>
        <child link="fl_wheel_link"/>
        <origin xyz="-0.0218084 0.067 0" rpy="0 0 0" />
        <axis xyz="0 0 1" rpy="0 0 0" />
    </joint>


    <link name="fr_castor_link">
        <visual>
            <origin xyz="0 0 0" rpy="0 0 0" />
            <geometry>
                <!--<cylinder length="${castor_length}" radius="${castor_radius}"/>-->
                <mesh filename="package://tracer_description/meshes/castor_joint.dae" />
            </geometry>
            <!--<material name="black">
                <color rgba="255 255 255 1"/>
            </material>-->
        </visual>
        <inertial>
            <mass value="1" />
            <origin xyz="0 0 0" />
            <inertia ixx="0.7171" ixy="0" ixz="0" iyy="0.1361" iyz="0" izz="0.7171" />
        </inertial>
    </link>

    <joint name="fr_castor_wheel" type="continuous">
        <parent link="base_link" />
        <child link="fr_castor_link" />
        <origin xyz="0.18905 -0.167575 -0.0280886" rpy="-1.57 0 0" />
        <axis xyz="0 1 0" rpy="0 0 0" />
    </joint>

    <link name="fr_wheel_link">
        <visual>
            <origin xyz="0 0 0" rpy="0 0 0" />
            <geometry>
            <!--<cylinder length="0.04653" radius="0.036"/>-->
            <!--<sphere radius="0.0457774"/>-->
                <mesh filename="package://tracer_description/meshes/castor.dae" />
            </geometry>
            <!--<material name="black">
            <color rgba="255 255 255 1"/>
            </material>-->
        </visual>

        <inertial>
                <mass value="1" />
                <origin xyz="0 0 0" />
                <inertia ixx="0.3131" ixy="0" ixz="0" iyy="0.3131" iyz="0" izz="0.1361" />
                <!--<inertia ixx="0" ixy="0" ixz="0" iyy="0" iyz="0" izz="0" />-->
        </inertial>
        <collision>
            <origin
            xyz="0 0 0"
            rpy="0 0 0" />
            <geometry>
                <!--<cylinder length="0.04653" radius="0.036"/>-->
                <!--<cylinder length="0.0787019" radius="0.0457774"/>-->
                <!--<sphere radius="0.0457774"/>-->
                <mesh filename="package://tracer_description/meshes/castor.dae" />
            </geometry>
        </collision>
    </link>

    <joint name="fr_wheel" type="continuous">
        <!-- <origin
                xyz="0.14547 0.20835 -0.07424"
                rpy="0 1.57 0" /> -->
        <parent link="fr_castor_link"/>
        <child link="fr_wheel_link"/>
        <origin xyz="-0.0218084 0.067 0" rpy="0 0 0" />
        <axis xyz="0 0 1" rpy="0 0 0" />
    </joint>

    <link name="rl_castor_link">
        <visual>
            <origin xyz="0 0 0" rpy="0 0 0" />
            <geometry>
                <!--<cylinder length="${castor_length}" radius="${castor_radius}"/>-->
                <mesh filename="package://tracer_description/meshes/castor_joint.dae" />
            </geometry>
            <!--<material name="black">
                <color rgba="255 255 255 1"/>
            </material>-->
        </visual>
        <inertial>
            <mass value="1" />
            <origin xyz="0 0 0" />
            <inertia ixx="0.7171" ixy="0" ixz="0" iyy="0.1361" iyz="0" izz="0.7171" />
        </inertial>
    </link>

    <joint name="rl_castor_wheel" type="continuous">
        <parent link="base_link" />
        <child link="rl_castor_link" />
        <origin xyz="-0.18905 0.167575 -0.0360886" rpy="-1.57 0 0" />
        <axis xyz="0 1 0" rpy="0 0 0" />
    </joint>

    <link name="rl_wheel_link">
        <visual>
            <origin xyz="0 0 0" rpy="0 0 0" />
            <geometry>
                <!--<cylinder length="0.04653" radius="0.036"/>-->
                <!--<sphere radius="0.0457774"/>-->
                <mesh filename="package://tracer_description/meshes/castor.dae" />
            </geometry>
            <!--<material name="black">
                <color rgba="255 255 255 1"/>
            </material>-->
        </visual>
        <inertial>
            <mass value="1" />
            <origin xyz="0 0 0" />
            <inertia ixx="0.3131" ixy="0" ixz="0" iyy="0.3131" iyz="0" izz="0.1361" />
            <!--<inertia ixx="0" ixy="0" ixz="0" iyy="0" iyz="0" izz="0" />-->
        </inertial>
        <collision>
            <origin
            xyz="0 0 0"
            rpy="0 0 0" />
            <geometry>
                <!--<cylinder length="0.04653" radius="0.036"/>-->
                <!--<cylinder length="0.0787019" radius="0.0457774"/>-->
                <!--<sphere radius="0.0457774"/>-->
                <mesh filename="package://tracer_description/meshes/castor.dae" />
            </geometry>
        </collision>
    </link>

    <joint name="rl_wheel" type="continuous">
        <!-- <origin
                xyz="0.14547 0.20835 -0.07424"
                rpy="0 1.57 0" /> -->
        <parent link="rl_castor_link"/>
        <child link="rl_wheel_link"/>
        <origin xyz="-0.0218084 0.067 0" rpy="0 0 0" />
        <axis xyz="0 0 1" rpy="0 0 0" />
    </joint>


    <link name="rr_castor_link">
        <visual>
            <origin xyz="0 0 0" rpy="0 0 0" />
            <geometry>
                <!--<cylinder length="${castor_length}" radius="${castor_radius}"/>-->
                <mesh filename="package://tracer_description/meshes/castor_joint.dae" />
            </geometry>
            <!-- <material name="black">
                <color rgba="255 255 255 1"/>
            </material>-->
        </visual>
        <inertial>
            <mass value="1" />
            <origin xyz="0 0 0" />
            <inertia ixx="0.7171" ixy="0" ixz="0" iyy="0.1361" iyz="0" izz="0.7171" />
        </inertial>
    </link>

    <joint name="rr_castor_wheel" type="continuous">
        <parent link="base_link" />
        <child link="rr_castor_link" />
        <origin xyz="-0.18905 -0.167575 -0.0380886" rpy="-1.57 0 0" />
        <axis xyz="0 1 0" rpy="0 0 0" />
    </joint>

    <link name="rr_wheel_link">
        <visual>
            <origin xyz="0 0 0" rpy="0 0 0" />
            <geometry>
                <!--<cylinder length="0.04653" radius="0.036"/>-->
                <!--<sphere radius="0.0457774"/>-->
                <mesh filename="package://tracer_description/meshes/castor.dae" />
            </geometry>
            <!--<material name="black">
                <color rgba="255 255 255 1"/>
            </material>-->
        </visual>
        <inertial>
            <mass value="1" />
            <origin xyz="0 0 0" />
            <inertia ixx="0.3131" ixy="0" ixz="0" iyy="0.3131" iyz="0" izz="0.1361" />
            <!--<inertia ixx="0" ixy="0" ixz="0" iyy="0" iyz="0" izz="0" />-->
        </inertial>
        <collision>
            <origin
            xyz="0 0 0"
            rpy="0 0 0" />
            <geometry>
                <!--<mesh filename="package://tracer_description/meshes/wheel.dae" />-->
                <!--<cylinder length="0.04653" radius="0.036"/>-->
                <!-- <sphere radius="0.0457774"/>-->
                <mesh filename="package://tracer_description/meshes/castor.dae" />
            </geometry>
        </collision>
    </link>

    <joint name="rr_wheel" type="continuous">
        <!-- <origin
                xyz="0.14547 0.20835 -0.07424"
                rpy="0 1.57 0" /> -->
        <parent link="rr_castor_link"/>
        <child link="rr_wheel_link"/>
        <origin xyz="-0.0218084 0.067 0" rpy="0 0 0" />
        <axis xyz="0 0 1" rpy="0 0 0" />
    </joint>


</robot>