<?xml version="1.0"?>
<robot name="tracer_v1">
    <!-- Base link -->
    <link name="base_link">
        <visual>
            <origin xyz="0 0 0" rpy="1.57 0 0"/>
            <geometry>
                <mesh filename="/home/mj/tracer-gazebo/src/tracer_description/meshes/tracer_base_link_no_wheel.dae" />
            </geometry>
        </visual>
        <collision>
            <origin xyz="0 0 0" rpy="1.57 0 0"/>
            <geometry>
                <mesh filename="/home/mj/tracer-gazebo/src/tracer_description/meshes/tracer_base_link_no_wheel.dae" />
            </geometry>
        </collision>
        <inertial>
            <mass value="132.3898489950015" />
            <origin xyz="0.015 0.0231316650320557 0" />
            <inertia ixx="0.185196122711036"
            ixy="4.30144213829512E-08"
            ixz="5.81037523686401E-08"
            iyy="0.364893736238929"
            iyz="-0.000386720198091934"
            izz="0.223868521722778" />
        </inertial>
    </link>

    <!-- Robot Footprint -->
    <link name="base_footprint"/>

    <joint name="base_joint" type="fixed">
        <parent link="base_footprint"/>
        <child link="base_link"/>
        <origin xyz="0.0 0.0 0.14" rpy="0 0 0"/>
    </joint>


    <!-- laser link -->
    <link name="laser_link">
        <visual>
            <origin xyz="0 0 0" rpy="0 0 0"/>
            <geometry>
                <cylinder length="0.02" radius="0.02"/>
            </geometry>
            <material name="black">
                <color rgba="0.0 0.0 0.0 0.5" /> 
            </material>
        </visual>
        <inertial>
            <mass value="0.1"/>
            <inertia ixx="0.000190416666667" ixy="0" ixz="0" iyy="0.0001904" iyz="0" izz="0.00036"/>
        </inertial>
    </link>
        
    <!-- laser joint -->
    <joint name="laser_joint" type="fixed">
        <parent link="base_link" />
        <child link="laser_link" />
        <origin xyz="0 0 0.03" />
    </joint>

    <link name="imu_link">
        <visual>
            <origin xyz="0 0 0.0" rpy="0 0 0"/>
            <geometry>
                    <box size="0.02 0.02 0.02"/>
            </geometry>
        </visual>
        <inertial>
            <mass value="0.1"/>
            <inertia ixx="0.000190416666667" ixy="0" ixz="0" iyy="0.0001904" iyz="0" izz="0.00036"/>
        </inertial>
    </link>

    <!-- imu joint -->
    <joint name="imu_joint" type="fixed">
        <parent link="base_link" />
        <child link="imu_link" />
        <origin xyz="0 0 0.01" />
    </joint>


    <link name="right_wheel_link">
        <visual>
            <origin xyz="0 0 0" rpy="0 0 0" />
            <geometry>
                <mesh filename="/home/mj/tracer-gazebo/src/tracer_description/meshes/tracer_wheel.dae" />
            </geometry>
        </visual>
        <inertial>
            <mass value="6" />
            <origin xyz="0 0 0" />
            <inertia ixx="0.7171" ixy="0" ixz="0" iyy="0.1361" iyz="0" izz="0.7171" />
        </inertial>
        <collision>
            <origin
            xyz="0 0 0"
            rpy="0 0 0" />
            <geometry>
                <mesh filename="/home/mj/tracer-gazebo/src/tracer_description/meshes/tracer_wheel.dae" />
                !--<cylinder length="0.0787019" radius="0.0457774"/>-->
            </geometry>
        </collision>
    </link>

    <joint name="right_wheel" type="continuous">
        <parent link="base_link"/>
        <child link="right_wheel_link"/>
        <origin xyz="0 -0.167575 -0.082" rpy="0 0 0" />
        <axis xyz="0 1 0" rpy="0 0 0" />
    </joint>

    <link name="left_wheel_link">
        <visual>
            <origin xyz="0 0 0" rpy="0 0 0" />
            <geometry>
                <mesh filename="/home/mj/tracer-gazebo/src/tracer_description/meshes/tracer_wheel.dae" />
            </geometry>
        </visual>
        <inertial>
            <mass value="6" />
            <origin xyz="0 0 0" />
            <inertia ixx="0.7171" ixy="0" ixz="0" iyy="0.1361" iyz="0" izz="0.7171" />
        </inertial>
        <collision>
            <origin
            xyz="0 0 0"
            rpy="0 0 0" />
            <geometry>
                <mesh filename="/home/mj/tracer-gazebo/src/tracer_description/meshes/tracer_wheel.dae" />
            </geometry>
        </collision>
    </link>

    <joint name="left_wheel" type="continuous">
        <parent link="base_link"/>
        <child link="left_wheel_link"/>
        <origin xyz="0 0.167575 -0.082" rpy="0 0 0" />
        <axis xyz="0 1 0" rpy="0 0 0" />
    </joint>

    <link name="fl_castor_link">
        <visual>
            <origin xyz="0 0 0" rpy="0 0 0" />
            <geometry>
                <mesh filename="/home/mj/tracer-gazebo/src/tracer_description/meshes/castor_joint.dae" />
            </geometry>
        </visual>
        <inertial>
            <mass value="1" />
            <origin xyz="0 0 0" />
            <inertia ixx="0.7171" ixy="0" ixz="0" iyy="0.1361" iyz="0" izz="0.7171" />
        </inertial>
    </link>

    <joint name="fl_castor_wheel" type="fixed">
        <parent link="base_link" />
        <child link="fl_castor_link" />
        <origin xyz="0.18905 0.167575 -0.0380886" rpy="-1.57 0 0" />
        <axis xyz="0 1 0" rpy="0 0 0" />
    </joint>

    <link name="fl_wheel_link">
        <visual>
            <origin xyz="0 0 0" rpy="0 0 0" />
            <geometry>
                <mesh filename="/home/mj/tracer-gazebo/src/tracer_description/meshes/castor.dae" />
            </geometry>
        </visual>
        <inertial>
            <mass value="1" />
            <origin xyz="0 0 0" />
            <inertia ixx="0.3131" ixy="0" ixz="0" iyy="0.3131" iyz="0" izz="0.1361" />
        </inertial>
        <collision>
            <origin
            xyz="0 0 0"
            rpy="0 0 0" />
            <geometry>
                <mesh filename="/home/mj/tracer-gazebo/src/tracer_description/meshes/castor.dae" />
            </geometry>
        </collision>
    </link>

    <joint name="fl_wheel" type="fixed">
        <parent link="fl_castor_link"/>
        <child link="fl_wheel_link"/>
        <origin xyz="-0.0218084 0.067 0" rpy="0 0 0" />
        <axis xyz="0 0 1" rpy="0 0 0" />
    </joint>


    <link name="fr_castor_link">
        <visual>
            <origin xyz="0 0 0" rpy="0 0 0" />
            <geometry>
                <mesh filename="/home/mj/tracer-gazebo/src/tracer_description/meshes/castor_joint.dae" />
            </geometry>
        </visual>
        <inertial>
            <mass value="1" />
            <origin xyz="0 0 0" />
            <inertia ixx="0.7171" ixy="0" ixz="0" iyy="0.1361" iyz="0" izz="0.7171" />
        </inertial>
    </link>

    <joint name="fr_castor_wheel" type="fixed">
        <parent link="base_link" />
        <child link="fr_castor_link" />
        <origin xyz="0.18905 -0.167575 -0.0280886" rpy="-1.57 0 0" />
        <axis xyz="0 1 0" rpy="0 0 0" />
    </joint>

    <link name="fr_wheel_link">
        <visual>
            <origin xyz="0 0 0" rpy="0 0 0" />
            <geometry>
                <mesh filename="/home/mj/tracer-gazebo/src/tracer_description/meshes/castor.dae" />
            </geometry>
        </visual>
        <inertial>
                <mass value="1" />
                <origin xyz="0 0 0" />
                <inertia ixx="0.3131" ixy="0" ixz="0" iyy="0.3131" iyz="0" izz="0.1361" />
        </inertial>
        <collision>
            <origin
            xyz="0 0 0"
            rpy="0 0 0" />
            <geometry>
                <mesh filename="/home/mj/tracer-gazebo/src/tracer_description/meshes/castor.dae" />
            </geometry>
        </collision>
    </link>

    <joint name="fr_wheel" type="fixed">
        <parent link="fr_castor_link"/>
        <child link="fr_wheel_link"/>
        <origin xyz="-0.0218084 0.067 0" rpy="0 0 0" />
        <axis xyz="0 0 1" rpy="0 0 0" />
    </joint>

    <link name="rl_castor_link">
        <visual>
            <origin xyz="0 0 0" rpy="0 0 0" />
            <geometry>
                <mesh filename="/home/mj/tracer-gazebo/src/tracer_description/meshes/castor_joint.dae" />
            </geometry>
        </visual>
        <inertial>
            <mass value="1" />
            <origin xyz="0 0 0" />
            <inertia ixx="0.7171" ixy="0" ixz="0" iyy="0.1361" iyz="0" izz="0.7171" />
        </inertial>
    </link>

    <joint name="rl_castor_wheel" type="fixed">
        <parent link="base_link" />
        <child link="rl_castor_link" />
        <origin xyz="-0.18905 0.167575 -0.0360886" rpy="-1.57 0 0" />
        <axis xyz="0 1 0" rpy="0 0 0" />
    </joint>

    <link name="rl_wheel_link">
        <visual>
            <origin xyz="0 0 0" rpy="0 0 0" />
            <geometry>
                <mesh filename="/home/mj/tracer-gazebo/src/tracer_description/meshes/castor.dae" />
            </geometry>
        </visual>
        <inertial>
            <mass value="1" />
            <origin xyz="0 0 0" />
            <inertia ixx="0.3131" ixy="0" ixz="0" iyy="0.3131" iyz="0" izz="0.1361" />
        </inertial>
        <collision>
            <origin
            xyz="0 0 0"
            rpy="0 0 0" />
            <geometry>
                <mesh filename="/home/mj/tracer-gazebo/src/tracer_description/meshes/castor.dae" />
            </geometry>
        </collision>
    </link>

    <joint name="rl_wheel" type="fixed">
        <parent link="rl_castor_link"/>
        <child link="rl_wheel_link"/>
        <origin xyz="-0.0218084 0.067 0" rpy="0 0 0" />
        <axis xyz="0 0 1" rpy="0 0 0" />
    </joint>


    <link name="rr_castor_link">
        <visual>
            <origin xyz="0 0 0" rpy="0 0 0" />
            <geometry>
                <mesh filename="/home/mj/tracer-gazebo/src/tracer_description/meshes/castor_joint.dae" />
            </geometry>
        </visual>
        <inertial>
            <mass value="1" />
            <origin xyz="0 0 0" />
            <inertia ixx="0.7171" ixy="0" ixz="0" iyy="0.1361" iyz="0" izz="0.7171" />
        </inertial>
    </link>

    <joint name="rr_castor_wheel" type="fixed">
        <parent link="base_link" />
        <child link="rr_castor_link" />
        <origin xyz="-0.18905 -0.167575 -0.0380886" rpy="-1.57 0 0" />
        <axis xyz="0 1 0" rpy="0 0 0" />
    </joint>

    <link name="rr_wheel_link">
        <visual>
            <origin xyz="0 0 0" rpy="0 0 0" />
            <geometry>
                <mesh filename="/home/mj/tracer-gazebo/src/tracer_description/meshes/castor.dae" />
            </geometry>
        </visual>
        <inertial>
            <mass value="1" />
            <origin xyz="0 0 0" />
            <inertia ixx="0.3131" ixy="0" ixz="0" iyy="0.3131" iyz="0" izz="0.1361" />
        </inertial>
        <collision>
            <origin
            xyz="0 0 0"
            rpy="0 0 0" />
            <geometry>
                <mesh filename="/home/mj/tracer-gazebo/src/tracer_description/meshes/castor.dae" />
            </geometry>
        </collision>
    </link>

    <joint name="rr_wheel" type="fixed">
        <parent link="rr_castor_link"/>
        <child link="rr_wheel_link"/>
        <origin xyz="-0.0218084 0.067 0" rpy="0 0 0" />
        <axis xyz="0 0 1" rpy="0 0 0" />
    </joint>

    <gazebo reference="fl_caster_link">
        <mu1 value="0.0"/>
        <mu2 value="0.0"/>
        <kp value="1000000.0" />
        <kd value="10.0" />
        <!-- <fdir1 value="0 0 1"/> -->
    </gazebo>
    <gazebo reference="fl_wheel_link">
        <mu1 value="0.0"/>
        <mu2 value="0.0"/>
        <kp value="1000000.0" />
        <kd value="10.0" />
        <!-- <fdir1 value="0 0 1"/> -->
    </gazebo>
    <gazebo reference="fr_caster_link">
        <mu1 value="0.0"/>
        <mu2 value="0.0"/>
        <kp value="1000000.0" />
        <kd value="10.0" />
        <!-- <fdir1 value="0 0 1"/> -->
    </gazebo>
    <gazebo reference="fr_wheel_link">
        <mu1 value="0.0"/>
        <mu2 value="0.0"/>
        <kp value="1000000.0" />
        <kd value="10.0" />
        <!-- <fdir1 value="0 0 1"/> -->
    </gazebo>
    <gazebo reference="rl_caster_link">
        <mu1 value="0.0"/>
        <mu2 value="0.0"/>
        <kp value="1000000.0" />
        <kd value="10.0" />
        <!-- <fdir1 value="0 0 1"/> -->
    </gazebo>
    <gazebo reference="rl_wheel_link">
        <mu1 value="0.0"/>
        <mu2 value="0.0"/>
        <kp value="1000000.0" />
        <kd value="10.0" />
        <!-- <fdir1 value="0 0 1"/> -->
    </gazebo>
    <gazebo reference="rr_caster_link">
        <mu1 value="0.0"/>
        <mu2 value="0.0"/>
        <kp value="1000000.0" />
        <kd value="10.0" />
        <!-- <fdir1 value="0 0 1"/> -->
    </gazebo>
    <gazebo reference="rr_wheel_link">
        <mu1 value="0.0"/>
        <mu2 value="0.0"/>
        <kp value="1000000.0" />
        <kd value="10.0" />
        <!-- <fdir1 value="0 0 1"/> -->
    </gazebo>


    <gazebo>
        <plugin name='diff_drive' filename='libgazebo_ros_diff_drive.so'>
            <ros>
                <namespace>/</namespace>
                <remapping>cmd_vel:=cmd_vel</remapping>
                <remapping>odom:=odom</remapping>
            </ros>
            <update_rate>30</update_rate>
            <!-- wheels -->
            <!-- <left_joint>left_wheel_joint</left_joint> -->
            <!-- <right_joint>right_wheel_joint</right_joint> -->
            <left_joint>left_wheel</left_joint>
            <right_joint>right_wheel</right_joint>
            <!-- kinematics -->
            <wheel_separation>033515</wheel_separation>
            <wheel_diameter>0.04</wheel_diameter>
            <!-- limits -->
            <max_wheel_torque>20</max_wheel_torque>
            <max_wheel_acceleration>1.0</max_wheel_acceleration>
            <!-- output -->
            <publish_odom>true</publish_odom>
            <publish_odom_tf>true</publish_odom_tf>
            <publish_wheel_tf>false</publish_wheel_tf>
            <odometry_frame>odom</odometry_frame>
            <robot_base_frame>base_footprint</robot_base_frame>
        </plugin>


        <plugin name="tracer_joint_state" filename="libgazebo_ros_joint_state_publisher.so">
            <ros>
            <remapping>~/out:=joint_states</remapping>
            </ros>
            <update_rate>30</update_rate>
            <joint_name>right_wheel</joint_name>
            <joint_name>left_wheel</joint_name> 
        </plugin>    
    </gazebo> 

</robot>